Workbook

Sheet Datasheet
D1: Quality (1=not achieved, 2=major deficits, 3=minor deficits, 4=best) | S1: Correctness (1=incorrect, 2=major issues, 3=minor issues, 4=correct)
B2: Mission requirement (generated by the LLM) | C2: Number of Tries | D2: Comb. avg. quality rating | E2: Prompt Engineer | L2: Evaluator | S2: Avg correctness rating | T2: Prompt Engineer | V2: Evaluator | AA2: Distance of Disagreement
A3: BT ID | E3: Avg. quality rating | F3: Atomicity | G3: Ambiguity | H3: Completeness | I3: Usability | J3: Consistency | K3: Comment | L3: Avg. quality rating | M3: Atomicity | N3: Ambiguity | O3: Completeness | P3: Usability | Q3: Consistency | R3: Comment | T3: Rating | U3: Comment | V3: Rating | W3: Comment | X3: Prompts | AA3: Atomicity | AB3: Ambiguity | AC3: Completeness | AD3: Usability | AE3: Consistency
A4: Cycle 1
A5: entry_6 | B5: https://github.com/isselab/2025-models-prompt-engineering-results/blob/main/experiment_samples/cycle_1/mrq_entry_6.txt | C5: 5 | D5: =AVERAGE(E5, L5) -> 2.4 | E5: =AVERAGE(F5, G5, H5, I5, J5) -> 2 | F5: 2 | G5: 2 | H5: 2 | I5: 1 | J5: 3 | K5: Misinterpreted code references. The LLM also included unecessary additional information (Behavioral Flow Reference Mapping) presented in an undesired format. Readability was bad | L5: =AVERAGE(M5, N5, O5, P5, Q5) -> 2.8 | M5: 2 | N5: 3 | O5: 4 | P5: 1 | Q5: 4 | R5: The requirement R11 addresses two atomic functions: “position its arms for grasping” and “navigate to the computed inverse pose”. It is possible to improve the readability of the requirements to enable non-technical users to understand the behavior captured. | S5: =AVERAGE(T5, V5) -> 3.5 | T5: 3 | U5: ask for help may not always be from a human. that detail is not entirely correct | V5: 4 | X5: https://github.com/isselab/2025-models-prompt-engineering-results/blob/main/experiment_samples/cycle_1/prompt_entry_6.txt | AA5: =ABS(F5-M5) -> 0 | AB5: =ABS(G5-N5) -> 1 | AC5: =ABS(H5-O5) -> 2 | AD5: =ABS(I5-P5) -> 0 | AE5: =ABS(J5-Q5) -> 1
A6: entry_64 | B6: https://github.com/isselab/2025-models-prompt-engineering-results/blob/main/experiment_samples/cycle_1/mrq_entry_64.txt | C6: 1 | D6: =AVERAGE(E6, L6) -> 2.7 | E6: =AVERAGE(F6, G6, H6, I6, J6) -> 2.6 | F6: 3 | G6: 3 | H6: 3 | I6: 1 | J6: 3 | K6: code references not consistently applied. readability was bad (usability <) | L6: =AVERAGE(M6, N6, O6, P6, Q6) -> 2.8 | M6: 4 | N6: 3 | O6: 4 | P6: 1 | Q6: 2 | R6: It is possible to improve the readability of the requirements to enable non-technical users to understand the behavior captured. R2 and R8 are redundant. | S6: =AVERAGE(T6, V6) -> 2.5 | T6: 2 | U6: REQ-7 not an accurate requirement. "interesting" cannot be readily inferred from visualizing the BT. REQ-2 and REQ-8 are the same (i.e. redundancy). REQ-13 not so accurate | V6: 3 | W6: R2 and R8 are redundant. | X6: https://github.com/isselab/2025-models-prompt-engineering-results/blob/main/experiment_samples/cycle_1/prompt_entry_64.txt | AA6: =ABS(F6-M6) -> 1 | AB6: =ABS(G6-N6) -> 0 | AC6: =ABS(H6-O6) -> 1 | AD6: =ABS(I6-P6) -> 0 | AE6: =ABS(J6-Q6) -> 1
A7: entry_73 | B7: https://github.com/isselab/2025-models-prompt-engineering-results/blob/main/experiment_samples/cycle_1/mrq_entry_73.txt | C7: 2 | D7: =AVERAGE(E7, L7) -> 2.7 | E7: =AVERAGE(F7, G7, H7, I7, J7) -> 2.8 | F7: 3 | G7: 3 | H7: 4 | I7: 1 | J7: 3 | K7: Note: The BT XML misspells “RetryUntilSuccessful” as “RetryUntilSuccesful,” but LLM uses the intended meaning. Readability was bad | L7: =AVERAGE(M7, N7, O7, P7, Q7) -> 2.6 | M7: 4 | N7: 2 | O7: 2 | P7: 1 | Q7: 4 | R7: In my opinion, some of the inferences may lead to vague requirements (minor incompleteness) due to a lack of information. For example, in R16, how would 'stable orientation' be verified (moderate ambiguity) ? It is possible to improve the readability of the requirements to enable non-technical users to understand the behavior captured. | S7: =AVERAGE(T7, V7) -> 2 | T7: 2 | U7: REQ-3: "reports a SUCCESS condition" is not so accurate. More like a SUCCESS status is returned. A lot of repetirion of concepts. Alot of inferred condition added to action, which may not necessarily be accurate. | V7: 2 | W7: R2, R5, R8 and R11 are difficult to understand. It is necessary to reorganize them. It is possible to improve the readability of the requirements to enable users unambiguously understand the behavior captured | X7: https://github.com/isselab/2025-models-prompt-engineering-results/blob/main/experiment_samples/cycle_1/prompt_entry_73.txt | AA7: =ABS(F7-M7) -> 1 | AB7: =ABS(G7-N7) -> 1 | AC7: =ABS(H7-O7) -> 2 | AD7: =ABS(I7-P7) -> 0 | AE7: =ABS(J7-Q7) -> 1
A8: entry_266 | B8: https://github.com/isselab/2025-models-prompt-engineering-results/blob/main/experiment_samples/cycle_1/mrq_entry_266.txt | C8: 2 | D8: =AVERAGE(E8, L8) -> 2.6 | E8: =AVERAGE(F8, G8, H8, I8, J8) -> 2.4 | F8: 2 | G8: 2 | H8: 3 | I8: 1 | J8: 4 | K8: Code reference misinterpretation. R5 not atomic at all. Bad usability | L8: =AVERAGE(M8, N8, O8, P8, Q8) -> 2.8 | M8: 3 | N8: 3 | O8: 3 | P8: 1 | Q8: 4 | R8: R5 is not atomic. It is not explicitly stated which inputs of one action are outputs of another. In my opinion, this point could be improved if it is a priority. It is possible to improve the readability of the requirements to enable non-technical users to understand the behavior captured. | S8: =AVERAGE(T8, V8) -> 3.5 | T8: 3 | U8: sequence is not explicitly state and input paramaters are mentioned but not defined as input parameters. | V8: 4 | X8: https://github.com/isselab/2025-models-prompt-engineering-results/blob/main/experiment_samples/cycle_1/prompt_entry_266.txt | AA8: =ABS(F8-M8) -> 1 | AB8: =ABS(G8-N8) -> 1 | AC8: =ABS(H8-O8) -> 0 | AD8: =ABS(I8-P8) -> 0 | AE8: =ABS(J8-Q8) -> 0
A9: entry_317 | B9: https://github.com/isselab/2025-models-prompt-engineering-results/blob/main/experiment_samples/cycle_1/mrq_entry_317.txt | C9: 2 | D9: =AVERAGE(E9, L9) -> 2.3 | E9: =AVERAGE(F9, G9, H9, I9, J9) -> 2.2 | F9: 1 | G9: 3 | H9: 3 | I9: 1 | J9: 3 | K9: Inconsistent language: "robot" and "system" mix in wording. Statements can be further decomposed into multiples. There are standalone requiremnts that are not labelled. Poor usabilty | L9: =AVERAGE(M9, N9, O9, P9, Q9) -> 2.4 | M9: 2 | N9: 2 | O9: 4 | P9: 1 | Q9: 3 | R9: Different linguistic patterns are used in the statements. This makes it difficult to understand the requirements in natural language. Some statements may be split into one or more statements. It is possible to improve the readability of the requirements to enable non-technical users to understand the behavior captured. | S9: =AVERAGE(T9, V9) -> 2.5 | T9: 2 | U9: Nuances like nested sequences and roud robin recovery techniques are not explained properly from the staments provided. Vague explanation of actions could lead to misinterpretations | V9: 3 | W9: The statements describe all the nodes of the BT, but the lack of standardization in the language used makes it difficult to validate their correctness. | X9: https://github.com/isselab/2025-models-prompt-engineering-results/blob/main/experiment_samples/cycle_1/prompt_entry_317.txt | AA9: =ABS(F9-M9) -> 1 | AB9: =ABS(G9-N9) -> 1 | AC9: =ABS(H9-O9) -> 1 | AD9: =ABS(I9-P9) -> 0 | AE9: =ABS(J9-Q9) -> 0
A10: entry_375 | B10: https://github.com/isselab/2025-models-prompt-engineering-results/blob/main/experiment_samples/cycle_1/mrq_entry_375.txt | C10: 1 | D10: =AVERAGE(E10, L10) -> 2.5 | E10: =AVERAGE(F10, G10, H10, I10, J10) -> 2.8 | F10: 1 | G10: 4 | H10: 4 | I10: 1 | J10: 4 | K10: one instance of "the system" instead of "the robot". Atomicity and usability is violated | L10: =AVERAGE(M10, N10, O10, P10, Q10) -> 2.2 | M10: 2 | N10: 2 | O10: 3 | P10: 1 | Q10: 3 | R10: R3 is not clear. R2 and R3 are not atomic. The statements interchange the terms robot and system. It is possible to improve the readability of the requirements to enable non-technical users to understand the behavior captured. | S10: =AVERAGE(T10, V10) -> 2.5 | T10: 3 | U10: Not the best accuracy and general presentation is bad so the understandability is affected and this may cause inferences to be made on the behavior exhibited. | V10: 2 | W10: R3 is not clear. The parameters "barout", "baz", and "fooin" are not explicitly defined, which makes them difficult to understand. | X10: https://github.com/isselab/2025-models-prompt-engineering-results/blob/main/experiment_samples/cycle_1/prompt_entry_375.txt | AA10: =ABS(F10-M10) -> 1 | AB10: =ABS(G10-N10) -> 2 | AC10: =ABS(H10-O10) -> 1 | AD10: =ABS(I10-P10) -> 0 | AE10: =ABS(J10-Q10) -> 1
A11: entry_411 | B11: https://github.com/isselab/2025-models-prompt-engineering-results/blob/main/experiment_samples/cycle_1/mrq_entry_411.txt | C11: 1 | D11: =AVERAGE(E11, L11) -> 2.4 | E11: =AVERAGE(F11, G11, H11, I11, J11) -> 2.2 | F11: 1 | G11: 4 | H11: 1 | I11: 1 | J11: 4 | K11: R12, R15, R16 are not atomic. Not usable. Code references misunderstood and it makes the text look clumsy. Usability was poor; a mix of code and natural language | L11: =AVERAGE(M11, N11, O11, P11, Q11) -> 2.6 | M11: 2 | N11: 2 | O11: 4 | P11: 1 | Q11: 4 | R11: Some statements are not atomic, for example, R12. The different formats of the statements make it difficult to interpret the description of the requirements in natural language. I think the lack of standardization in the text can lead to ambiguity. It is possible to improve the readability of the requirements to enable non-technical users to understand the behavior captured. | S11: =AVERAGE(T11, V11) -> 3 | T11: 3 | V11: 3 | W11: The presentation is not organized and is hard to follow; consequently, the described behavior might be misinterpreted | X11: https://github.com/isselab/2025-models-prompt-engineering-results/blob/main/experiment_samples/cycle_1/prompt_entry_411.txt | AA11: =ABS(F11-M11) -> 1 | AB11: =ABS(G11-N11) -> 2 | AC11: =ABS(H11-O11) -> 3 | AD11: =ABS(I11-P11) -> 0 | AE11: =ABS(J11-Q11) -> 0
A12: entry_457 | B12: https://github.com/isselab/2025-models-prompt-engineering-results/blob/main/experiment_samples/cycle_1/mrq_entry_457.txt | C12: 1 | D12: =AVERAGE(E12, L12) -> 2.2 | E12: =AVERAGE(F12, G12, H12, I12, J12) -> 2 | F12: 1 | G12: 2 | H12: 3 | I12: 1 | J12: 3 | K12: R11 AND R12 atomicity issues. Also no code references included. "if impassable" sounds a little contradictory. Poor presentation | L12: =AVERAGE(M12, N12, O12, P12, Q12) -> 2.4 | M12: 2 | N12: 2 | O12: 4 | P12: 1 | Q12: 3 | R12: The wording mixes 'system' and 'vehicle'. Furthermore, requirements like R4, R11, and R12 should be broken down into atomic statements. It is possible to improve the readability of the requirements to enable non-technical users to understand the behavior captured. | S12: =AVERAGE(T12, V12) -> 3 | T12: 3 | V12: 3 | W12: The lack of standardization in the language used makes it difficult to validate their correctness. | X12: https://github.com/isselab/2025-models-prompt-engineering-results/blob/main/experiment_samples/cycle_1/prompt_entry_457.txt | AA12: =ABS(F12-M12) -> 1 | AB12: =ABS(G12-N12) -> 0 | AC12: =ABS(H12-O12) -> 1 | AD12: =ABS(I12-P12) -> 0 | AE12: =ABS(J12-Q12) -> 0
A13: entry_467 | B13: https://github.com/isselab/2025-models-prompt-engineering-results/blob/main/experiment_samples/cycle_1/mrq_entry_467.txt | C13: 1 | D13: =AVERAGE(E13, L13) -> 2.8 | E13: =AVERAGE(F13, G13, H13, I13, J13) -> 3 | F13: 3 | G13: 4 | H13: 3 | I13: 1 | J13: 4 | K13: "the object" instead of the robot. Code references that are not easily understandable. Poor presentation | L13: =AVERAGE(M13, N13, O13, P13, Q13) -> 2.6 | M13: 3 | N13: 2 | O13: 4 | P13: 1 | Q13: 3 | R13: The statements mix the words 'system', 'robot', 'vehicle', and 'manipulator'. It is possible to improve the readability of the requirements. I think some statements are not atomic, for example, R1 and R5. | S13: =AVERAGE(T13, V13) -> 3 | T13: 3 | V13: 3 | W13: The interpreted behavior is correct; however, mixing terminology can lead to misinterpretation (e.g., 'system', 'robot', 'vehicle', and 'manipulator'). | X13: https://github.com/isselab/2025-models-prompt-engineering-results/blob/main/experiment_samples/cycle_1/prompt_entry_467.txt | AA13: =ABS(F13-M13) -> 0 | AB13: =ABS(G13-N13) -> 2 | AC13: =ABS(H13-O13) -> 1 | AD13: =ABS(I13-P13) -> 0 | AE13: =ABS(J13-Q13) -> 1
A14: entry_540 | B14: https://github.com/isselab/2025-models-prompt-engineering-results/blob/main/experiment_samples/cycle_1/mrq_entry_540.txt | C14: 1 | D14: =AVERAGE(E14, L14) -> 2.8 | E14: =AVERAGE(F14, G14, H14, I14, J14) -> 2.8 | F14: 1 | G14: 4 | H14: 4 | I14: 1 | J14: 4 | K14: too much contextual info given. Minor ordering issue. Poorly presented. thus not usable | L14: =AVERAGE(M14, N14, O14, P14, Q14) -> 2.8 | M14: 4 | N14: 2 | O14: 4 | P14: 1 | Q14: 3 | R14: The description can be simplified in terms of technical detail. Redundant info make it long. | S14: =AVERAGE(T14, V14) -> 3 | T14: 2 | U14: key execution nuance missed in interpreting SequencStar | V14: 4 | X14: https://github.com/isselab/2025-models-prompt-engineering-results/blob/main/experiment_samples/cycle_1/prompt_entry_540.txt | AA14: =ABS(F14-M14) -> 3 | AB14: =ABS(G14-N14) -> 2 | AC14: =ABS(H14-O14) -> 0 | AD14: =ABS(I14-P14) -> 0 | AE14: =ABS(J14-Q14) -> 1
A15: Cycle 2
A16: entry_150 | B16: https://github.com/isselab/2025-models-prompt-engineering-results/blob/main/experiment_samples/cycle_2/mrq_entry_150.txt | C16: 4 | D16: =AVERAGE(E16, L16) -> 3.1 | E16: =AVERAGE(F16, G16, H16, I16, J16) -> 3 | F16: 2 | G16: 4 | H16: 4 | I16: 1 | J16: 4 | K16: Some statements are not atomic enough | L16: =AVERAGE(M16, N16, O16, P16, Q16) -> 3.2 | M16: 4 | N16: 3 | O16: 4 | P16: 1 | Q16: 4 | R16: It is possible to improve the readability of the requirements to enable users unambiguously understand the behavior captured | S16: =AVERAGE(T16, V16) -> 4 | T16: 4 | V16: 4 | X16: https://github.com/isselab/2025-models-prompt-engineering-results/blob/main/experiment_samples/cycle_2/prompt_entry_150.txt | AA16: =ABS(F16-M16) -> 2 | AB16: =ABS(G16-N16) -> 1 | AC16: =ABS(H16-O16) -> 0 | AD16: =ABS(I16-P16) -> 0 | AE16: =ABS(J16-Q16) -> 0
A17: entry_220 | B17: https://github.com/isselab/2025-models-prompt-engineering-results/blob/main/experiment_samples/cycle_2/mrq_entry_220.txt | C17: 5 | D17: =AVERAGE(E17, L17) -> 2.8 | E17: =AVERAGE(F17, G17, H17, I17, J17) -> 2.8 | F17: 3 | G17: 3 | H17: 3 | I17: 1 | J17: 4 | K17: Few statements like (Global Fallback Path Handling 6.) are not atomic, some terminilogies are ambiguous without prior context from an overview | L17: =AVERAGE(M17, N17, O17, P17, Q17) -> 2.8 | M17: 3 | N17: 2 | O17: 4 | P17: 1 | Q17: 4 | R17: The presentation is not organized and is hard to follow. It is possible to improve the readability of the requirements to enable users unambiguously understand the behavior captured. Some statements are not atomic (e.g. Lane Keeping State 4.) | S17: =AVERAGE(T17, V17) -> 3 | T17: 3 | U17: Some ambiguities in the sentence formulation may affect correctness slightly | V17: 3 | W17: The description could be improved to make the content clearer. | X17: https://github.com/isselab/2025-models-prompt-engineering-results/blob/main/experiment_samples/cycle_2/prompt_entry_220.txt | AA17: =ABS(F17-M17) -> 0 | AB17: =ABS(G17-N17) -> 1 | AC17: =ABS(H17-O17) -> 1 | AD17: =ABS(I17-P17) -> 0 | AE17: =ABS(J17-Q17) -> 0
A18: entry_272 | B18: https://github.com/isselab/2025-models-prompt-engineering-results/blob/main/experiment_samples/cycle_2/mrq_entry_272.txt | C18: 1 | D18: =AVERAGE(E18, L18) -> 3.1 | E18: =AVERAGE(F18, G18, H18, I18, J18) -> 3 | F18: 3 | G18: 4 | H18: 3 | I18: 1 | J18: 4 | K18: I think maybe MRQ2 can be decomposed into more than one atomic statement. The statement seems complex and loaded. Not very usable in sentence formulation and presentation. Incomplete without an overview | L18: =AVERAGE(M18, N18, O18, P18, Q18) -> 3.2 | M18: 4 | N18: 3 | O18: 4 | P18: 1 | Q18: 4 | R18: It is possible to improve the readability of the requirements to enable users unambiguously understand the behavior captured. | S18: =AVERAGE(T18, V18) -> 4 | T18: 4 | V18: 4 | X18: https://github.com/isselab/2025-models-prompt-engineering-results/blob/main/experiment_samples/cycle_2/prompt_entry_272.txt | AA18: =ABS(F18-M18) -> 1 | AB18: =ABS(G18-N18) -> 1 | AC18: =ABS(H18-O18) -> 1 | AD18: =ABS(I18-P18) -> 0 | AE18: =ABS(J18-Q18) -> 0
A19: entry_418 | B19: https://github.com/isselab/2025-models-prompt-engineering-results/blob/main/experiment_samples/cycle_2/mrq_entry_418.txt | C19: 1 | D19: =AVERAGE(E19, L19) -> 3.1 | E19: =AVERAGE(F19, G19, H19, I19, J19) -> 3.2 | F19: 3 | G19: 4 | H19: 4 | I19: 1 | J19: 4 | K19: Usability still a challenge | L19: =AVERAGE(M19, N19, O19, P19, Q19) -> 3 | M19: 3 | N19: 3 | O19: 4 | P19: 1 | Q19: 4 | R19: Some statements are not atomic (e.g. R22). It is possible to improve the readability of the requirements to enable users unambiguously understand the behavior captured. | S19: =AVERAGE(T19, V19) -> 4 | T19: 4 | V19: 4 | X19: https://github.com/isselab/2025-models-prompt-engineering-results/blob/main/experiment_samples/cycle_2/prompt_entry_418.txt | AA19: =ABS(F19-M19) -> 0 | AB19: =ABS(G19-N19) -> 1 | AC19: =ABS(H19-O19) -> 0 | AD19: =ABS(I19-P19) -> 0 | AE19: =ABS(J19-Q19) -> 0
A20: entry_451 | B20: https://github.com/isselab/2025-models-prompt-engineering-results/blob/main/experiment_samples/cycle_2/mrq_entry_451.txt | C20: 1 | D20: =AVERAGE(E20, L20) -> 2.8 | E20: =AVERAGE(F20, G20, H20, I20, J20) -> 2.6 | F20: 3 | G20: 2 | H20: 4 | I20: 1 | J20: 3 | K20: MRQ3 not atomic. Not very usable; highly technical tone. Remembrance in MRQ13 not round specific. "ends unsuccessfully" is quite ambiguous and contradictory. | L20: =AVERAGE(M20, N20, O20, P20, Q20) -> 3 | M20: 3 | N20: 3 | O20: 4 | P20: 1 | Q20: 4 | R20: It is possible to improve the readability of the requirements to enable users unambiguously understand the behavior captured. Some statements are not atomic (e.g. R3) | S20: =AVERAGE(T20, V20) -> 4 | T20: 4 | V20: 4 | X20: https://github.com/isselab/2025-models-prompt-engineering-results/blob/main/experiment_samples/cycle_2/prompt_entry_451.txt | AA20: =ABS(F20-M20) -> 0 | AB20: =ABS(G20-N20) -> 1 | AC20: =ABS(H20-O20) -> 0 | AD20: =ABS(I20-P20) -> 0 | AE20: =ABS(J20-Q20) -> 1
A21: entry_475 | B21: https://github.com/isselab/2025-models-prompt-engineering-results/blob/main/experiment_samples/cycle_2/mrq_entry_475.txt | C21: 1 | D21: =AVERAGE(E21, L21) -> 2.9 | E21: =AVERAGE(F21, G21, H21, I21, J21) -> 3 | F21: 4 | G21: 4 | H21: 3 | I21: 1 | J21: 3 | K21: Instances of SequenceStar vaguely described. Poor usability. "the Fallback continues to other children (none exist)"---contradiction | L21: =AVERAGE(M21, N21, O21, P21, Q21) -> 2.8 | M21: 4 | N21: 2 | O21: 3 | P21: 1 | Q21: 4 | R21: I didn't understand REQ19 (text "none exist"). Is this a modeling issue?: "19. If the SequenceStar inside the Fallback returns FAILURE, the Fallback continues to other children (none exist), resulting in FAILURE." It is possible to improve the readability of the requirements | S21: =AVERAGE(T21, V21) -> 4 | T21: 4 | V21: 4 | X21: https://github.com/isselab/2025-models-prompt-engineering-results/blob/main/experiment_samples/cycle_2/prompt_entry_475.txt | AA21: =ABS(F21-M21) -> 0 | AB21: =ABS(G21-N21) -> 2 | AC21: =ABS(H21-O21) -> 0 | AD21: =ABS(I21-P21) -> 0 | AE21: =ABS(J21-Q21) -> 1
A22: entry_50 | B22: https://github.com/isselab/2025-models-prompt-engineering-results/blob/main/experiment_samples/cycle_2/mrq_entry_50.txt | C22: 1 | D22: =AVERAGE(E22, L22) -> 3.2 | E22: =AVERAGE(F22, G22, H22, I22, J22) -> 3.2 | F22: 3 | G22: 4 | H22: 4 | I22: 2 | J22: 3 | K22: MRQ 5 &6 display a repeatition in behavior. No general context orvierview of BT behavior; These affect usability drastically. Requirements are quite technical. | L22: =AVERAGE(M22, N22, O22, P22, Q22) -> 3.2 | M22: 4 | N22: 2 | O22: 4 | P22: 2 | Q22: 4 | R22: It is possible to improve the readability of the requirements to enable users unambiguously understand the behavior captured | S22: =AVERAGE(T22, V22) -> 4 | T22: 4 | V22: 4 | X22: https://github.com/isselab/2025-models-prompt-engineering-results/blob/main/experiment_samples/cycle_2/prompt_entry_50.txt | AA22: =ABS(F22-M22) -> 1 | AB22: =ABS(G22-N22) -> 2 | AC22: =ABS(H22-O22) -> 0 | AD22: =ABS(I22-P22) -> 0 | AE22: =ABS(J22-Q22) -> 1
A23: entry_511 | B23: https://github.com/isselab/2025-models-prompt-engineering-results/blob/main/experiment_samples/cycle_2/mrq_entry_511.txt | C23: 1 | D23: =AVERAGE(E23, L23) -> 2.8 | E23: =AVERAGE(F23, G23, H23, I23, J23) -> 2.6 | F23: 3 | G23: 3 | H23: 2 | I23: 2 | J23: 3 | K23: MRQ9 and MRQ17 are both ambiguous. both use the phrase "repeating as necessary" with no maximum iteration count or guard condition. Only mrqs 3, 5, 11, 13, 19, 22 are truly atomic. Mostly consistent aside a couple of consistency issues | L23: =AVERAGE(M23, N23, O23, P23, Q23) -> 3 | M23: 4 | N23: 2 | O23: 4 | P23: 1 | Q23: 4 | R23: Very technical terms are being used. Understandability could be improved for non-technical stakeholders. | S23: =AVERAGE(T23, V23) -> 3.5 | T23: 3 | U23: "repeating as necessary" phrase lacks precision | V23: 4 | X23: https://github.com/isselab/2025-models-prompt-engineering-results/blob/main/experiment_samples/cycle_2/prompt_entry_511.txt | AA23: =ABS(F23-M23) -> 1 | AB23: =ABS(G23-N23) -> 1 | AC23: =ABS(H23-O23) -> 2 | AD23: =ABS(I23-P23) -> 1 | AE23: =ABS(J23-Q23) -> 1
A24: entry_529 | B24: https://github.com/isselab/2025-models-prompt-engineering-results/blob/main/experiment_samples/cycle_2/mrq_entry_529.txt | C24: 1 | D24: =AVERAGE(E24, L24) -> 3 | E24: =AVERAGE(F24, G24, H24, I24, J24) -> 2.8 | F24: 3 | G24: 2 | H24: 3 | I24: 2 | J24: 4 | K24: Apart from MRRQ2 and 7 which are strongly atomic, the rest are moderately atomic. Ambiguity points: "1.0" has not unit. Does "halt" cancel execution or return failure or both? wait doesnt specify if its infinity or timed. MRQ 1 lacks the specific actions that should be executed. | L24: =AVERAGE(M24, N24, O24, P24, Q24) -> 3.2 | M24: 4 | N24: 2 | O24: 4 | P24: 2 | Q24: 4 | R24: It is possible to improve the readability of the requirements to enable users unambiguously understand the behavior captured | S24: =AVERAGE(T24, V24) -> 3.5 | T24: 3 | U24: ambiguity points stated impact correctness score | V24: 4 | X24: https://github.com/isselab/2025-models-prompt-engineering-results/blob/main/experiment_samples/cycle_2/prompt_entry_529.txt | AA24: =ABS(F24-M24) -> 1 | AB24: =ABS(G24-N24) -> 0 | AC24: =ABS(H24-O24) -> 1 | AD24: =ABS(I24-P24) -> 0 | AE24: =ABS(J24-Q24) -> 0
A25: entry_531 | B25: https://github.com/isselab/2025-models-prompt-engineering-results/blob/main/experiment_samples/cycle_2/mrq_entry_531.txt | C25: 1 | D25: =AVERAGE(E25, L25) -> 2.8 | E25: =AVERAGE(F25, G25, H25, I25, J25) -> 2.8 | F25: 3 | G25: 3 | H25: 3 | I25: 2 | J25: 3 | K25: MRQ9 could be split into subs. "is needed" is ambiguous and implicit (how that is determined, not specified). "specified smoother" (MRQ8) is too vague. round-robin is described implicitly. MRQ12 is not usable and describes a behavior that is not found in visualizer; reactivity seems like a full retry | L25: =AVERAGE(M25, N25, O25, P25, Q25) -> 2.8 | M25: 3 | N25: 2 | O25: 4 | P25: 1 | Q25: 4 | R25: Some statements are not atomic, for example, R6. In general, the requirements are not easy to understand; for example, R6, R9, R11, and R14 are particularly technical. My suggestion is to make them less technical. | S25: =AVERAGE(T25, V25) -> 3.5 | T25: 3 | U25: Some of the quality discrepancies detected impact the correctness of the description | V25: 4 | X25: https://github.com/isselab/2025-models-prompt-engineering-results/blob/main/experiment_samples/cycle_2/prompt_entry_531.txt | AA25: =ABS(F25-M25) -> 0 | AB25: =ABS(G25-N25) -> 1 | AC25: =ABS(H25-O25) -> 1 | AD25: =ABS(I25-P25) -> 1 | AE25: =ABS(J25-Q25) -> 1
A26: Cycle 3
A27: entry_58 | B27: https://github.com/isselab/2025-models-prompt-engineering-results/blob/main/experiment_samples/cycle_3/mrq_entry_58.txt | C27: 3 | D27: =AVERAGE(E27, L27) -> 3.2 | E27: =AVERAGE(F27, G27, H27, I27, J27) -> 3.2 | F27: 4 | G27: 3 | H27: 3 | I27: 2 | J27: 4 | K27: A few phrases lack precision:"Wait until go1/go2 completes","Report mission failure". Running status not covered. Req 1 uses the word "sequence" but the actual logic could be percieved as conditional branching i.e. not wrong, but slightly misleadingmisleading. | L27: =AVERAGE(M27, N27, O27, P27, Q27) -> 3.2 | M27: 4 | N27: 3 | O27: 3 | P27: 2 | Q27: 4 | R27: This description does not include details about go1 and go2. This affects completeness. It is possible to improve the readability of the requirements to enable users unambiguously understand the behavior captured | S27: =AVERAGE(T27, V27) -> 4 | T27: 4 | V27: 4 | X27: https://github.com/isselab/2025-models-prompt-engineering-results/blob/main/experiment_samples/cycle_3/prompt_entry_58.txt | AA27: =ABS(F27-M27) -> 0 | AB27: =ABS(G27-N27) -> 0 | AC27: =ABS(H27-O27) -> 0 | AD27: =ABS(I27-P27) -> 0 | AE27: =ABS(J27-Q27) -> 0
A28: entry_77 | B28: https://github.com/isselab/2025-models-prompt-engineering-results/blob/main/experiment_samples/cycle_3/mrq_entry_77.txt | C28: 1 | D28: =AVERAGE(E28, L28) -> 2.8 | E28: =AVERAGE(F28, G28, H28, I28, J28) -> 2.6 | F28: 3 | G28: 3 | H28: 3 | I28: 1 | J28: 3 | K28: MRQ8 can be split into a main and sub. MRQ7: "stop the current sequence and terminate the current cycle";oes terminating a cycle mean the mission proceeds to the next cycle, or halts entirely?Its also not clear what a cycle is. Sounds very technical and presentation makes readability slightly difficult. "Three complete cycles" (MRQ1), "three successfully executed" (MRQ8), and "three successful cycles" (MRQ9) all phrase the same condition differently, introducing subtle interpretive risk. | L28: =AVERAGE(M28, N28, O28, P28, Q28) -> 3 | M28: 3 | N28: 3 | O28: 4 | P28: 1 | Q28: 4 | R28: Very technical terms are being used. Understandability could be improved for non-technical stakeholders. R8 is not atomic. | S28: =AVERAGE(T28, V28) -> 3.5 | T28: 3 | U28: Interpretation risk in 8 and 9 dents the correctness a bit | V28: 4 | X28: https://github.com/isselab/2025-models-prompt-engineering-results/blob/main/experiment_samples/cycle_3/prompt_entry_77.txt | AA28: =ABS(F28-M28) -> 0 | AB28: =ABS(G28-N28) -> 0 | AC28: =ABS(H28-O28) -> 1 | AD28: =ABS(I28-P28) -> 0 | AE28: =ABS(J28-Q28) -> 1
A29: entry_92 | B29: https://github.com/isselab/2025-models-prompt-engineering-results/blob/main/experiment_samples/cycle_3/mrq_entry_92.txt | C29: 1 | D29: =AVERAGE(E29, L29) -> 3 | E29: =AVERAGE(F29, G29, H29, I29, J29) -> 3.2 | F29: 3 | G29: 4 | H29: 3 | I29: 2 | J29: 4 | K29: MRQ29 can be reforemulated into two requirements. No timeout policy for continuously evaluated conditions. Any and all not used consistently. Usability level not strong enough to realsie mission in detail. | L29: =AVERAGE(M29, N29, O29, P29, Q29) -> 2.8 | M29: 3 | N29: 3 | O29: 4 | P29: 1 | Q29: 3 | R29: The output may be simplified. Redundant rules for similar behaviors could be optimized. R29 and R33 are not atomic. It is possible to improve the readability of the requirements to enable users unambiguously understand the behavior captured | S29: =AVERAGE(T29, V29) -> 4 | T29: 4 | V29: 4 | X29: https://github.com/isselab/2025-models-prompt-engineering-results/blob/main/experiment_samples/cycle_3/prompt_entry_92.txt | AA29: =ABS(F29-M29) -> 0 | AB29: =ABS(G29-N29) -> 1 | AC29: =ABS(H29-O29) -> 1 | AD29: =ABS(I29-P29) -> 1 | AE29: =ABS(J29-Q29) -> 1
A30: entry_124 | B30: https://github.com/isselab/2025-models-prompt-engineering-results/blob/main/experiment_samples/cycle_3/mrq_entry_124.txt | C30: 5 | D30: =AVERAGE(E30, L30) -> 2.9 | E30: =AVERAGE(F30, G30, H30, I30, J30) -> 2.8 | F30: 4 | G30: 3 | H30: 2 | I30: 1 | J30: 4 | K30: Repetition is specified in categorised list heading instead of being fused into description. Failure state handing (11-28) not addressed. | L30: =AVERAGE(M30, N30, O30, P30, Q30) -> 3 | M30: 4 | N30: 2 | O30: 4 | P30: 1 | Q30: 4 | R30: Very technical terms are being used. Understandability could be improved for non-technical stakeholders. | S30: =AVERAGE(T30, V30) -> 3.5 | T30: 3 | U30: Some execution states are not mentioned but implied and left to user interpretation so this could be interpreted as incomplete and imprecise | V30: 4 | X30: https://github.com/isselab/2025-models-prompt-engineering-results/blob/main/experiment_samples/cycle_3/prompt_entry_124.txt | AA30: =ABS(F30-M30) -> 0 | AB30: =ABS(G30-N30) -> 1 | AC30: =ABS(H30-O30) -> 2 | AD30: =ABS(I30-P30) -> 0 | AE30: =ABS(J30-Q30) -> 0
A31: entry_155 | B31: https://github.com/isselab/2025-models-prompt-engineering-results/blob/main/experiment_samples/cycle_3/mrq_entry_155.txt | C31: 1 | D31: =AVERAGE(E31, L31) -> 3.4 | E31: =AVERAGE(F31, G31, H31, I31, J31) -> 3.6 | F31: 4 | G31: 3 | H31: 4 | I31: 3 | J31: 4 | K31: The phrase "Wait until the action completes before proceeding" sounds ambiguous | L31: =AVERAGE(M31, N31, O31, P31, Q31) -> 3.2 | M31: 4 | N31: 2 | O31: 4 | P31: 2 | Q31: 4 | R31: Usability can be improved for non-technical stakeholders. I think improving readability can prevent ambiguities. | S31: =AVERAGE(T31, V31) -> 4 | T31: 4 | V31: 4 | X31: https://github.com/isselab/2025-models-prompt-engineering-results/blob/main/experiment_samples/cycle_3/prompt_entry_155.txt | AA31: =ABS(F31-M31) -> 0 | AB31: =ABS(G31-N31) -> 1 | AC31: =ABS(H31-O31) -> 0 | AD31: =ABS(I31-P31) -> 1 | AE31: =ABS(J31-Q31) -> 0
A32: entry_248 | B32: https://github.com/isselab/2025-models-prompt-engineering-results/blob/main/experiment_samples/cycle_3/mrq_entry_248.txt | C32: 5 | D32: =AVERAGE(E32, L32) -> 2.6 | E32: =AVERAGE(F32, G32, H32, I32, J32) -> 2.6 | F32: 3 | G32: 3 | H32: 3 | I32: 1 | J32: 3 | K32: MRQ3,16,21 can be split into multiple sentences. MRQ22: "restart the sequence from the first action"; contradicts SequenceStar behavior. MRQ24 retry count comes off as ambiguous. Is the initial try part of the six retries? | L32: =AVERAGE(M32, N32, O32, P32, Q32) -> 2.6 | M32: 3 | N32: 2 | O32: 4 | P32: 1 | Q32: 3 | R32: "complete the mission" in R25 and "terminate the mission" in R26 seem to be the same thing, but they are not. I think this can lead to ambiguity. R21 can be rearranged in terms of atomicity. This matches BT entry_418 (Cycle 2); however, the description of the requirements has been refined | S32: =AVERAGE(T32, V32) -> 4 | T32: 4 | V32: 4 | X32: https://github.com/isselab/2025-models-prompt-engineering-results/blob/main/experiment_samples/cycle_3/prompt_entry_248.txt | AA32: =ABS(F32-M32) -> 0 | AB32: =ABS(G32-N32) -> 1 | AC32: =ABS(H32-O32) -> 1 | AD32: =ABS(I32-P32) -> 0 | AE32: =ABS(J32-Q32) -> 0
A33: entry_256 | B33: https://github.com/isselab/2025-models-prompt-engineering-results/blob/main/experiment_samples/cycle_3/mrq_entry_256.txt | C33: 1 | D33: =AVERAGE(E33, L33) -> 3.1 | E33: =AVERAGE(F33, G33, H33, I33, J33) -> 3.2 | F33: 4 | G33: 3 | H33: 3 | I33: 2 | J33: 4 | K33: does the mission then proceed to the next cycle, or does it abort all remaining cycles when it terminates sequence execution for that cycle?; A bit of ambiguity there | L33: =AVERAGE(M33, N33, O33, P33, Q33) -> 3 | M33: 3 | N33: 3 | O33: 4 | P33: 1 | Q33: 4 | R33: "inout ports" in R11 can be rewritten as "in/out ports". R11 is not atomic. Very technical terms are being used. Understandability could be improved for non-technical stakeholders. | S33: =AVERAGE(T33, V33) -> 4 | T33: 4 | V33: 4 | X33: https://github.com/isselab/2025-models-prompt-engineering-results/blob/main/experiment_samples/cycle_3/prompt_entry_256.txt | AA33: =ABS(F33-M33) -> 1 | AB33: =ABS(G33-N33) -> 0 | AC33: =ABS(H33-O33) -> 1 | AD33: =ABS(I33-P33) -> 1 | AE33: =ABS(J33-Q33) -> 0
A34: entry_345 | B34: https://github.com/isselab/2025-models-prompt-engineering-results/blob/main/experiment_samples/cycle_3/mrq_entry_345.txt | C34: 1 | D34: =AVERAGE(E34, L34) -> 3.2 | E34: =AVERAGE(F34, G34, H34, I34, J34) -> 3.2 | F34: 4 | G34: 4 | H34: 3 | I34: 1 | J34: 4 | K34: Presentation hampers readability and understandability to a significant extent | L34: =AVERAGE(M34, N34, O34, P34, Q34) -> 3.2 | M34: 4 | N34: 3 | O34: 4 | P34: 1 | Q34: 4 | R34: R2, R5, R8 and R11 are difficult to understand. Maybe we could reorganize them. It is possible to improve the readability of the requirements to enable users unambiguously understand the behavior captured | S34: =AVERAGE(T34, V34) -> 4 | T34: 4 | V34: 4 | X34: https://github.com/isselab/2025-models-prompt-engineering-results/blob/main/experiment_samples/cycle_3/prompt_entry_345.txt | AA34: =ABS(F34-M34) -> 0 | AB34: =ABS(G34-N34) -> 1 | AC34: =ABS(H34-O34) -> 1 | AD34: =ABS(I34-P34) -> 0 | AE34: =ABS(J34-Q34) -> 0
A35: entry_380 | B35: https://github.com/isselab/2025-models-prompt-engineering-results/blob/main/experiment_samples/cycle_3/mrq_entry_380.txt | C35: 1 | D35: =AVERAGE(E35, L35) -> 3.2 | E35: =AVERAGE(F35, G35, H35, I35, J35) -> 3.4 | F35: 4 | G35: 4 | H35: 4 | I35: 2 | J35: 3 | K35: MRQ6 is redundant. MRQ4 and 8 overlap. Seems readable and undestandable. Some strict details are missing but it doesnt hamper reproducibility | L35: =AVERAGE(M35, N35, O35, P35, Q35) -> 3 | M35: 4 | N35: 3 | O35: 2 | P35: 2 | Q35: 4 | R35: The parameters "barout", "baz", and "fooin" were omitted. This BT is very similar to entry_375 (Cycle 1). Usability can be improved for non-technical stakeholders. I think improving readability can prevent ambiguities | S35: =AVERAGE(T35, V35) -> 3 | T35: 3 | U35: Lack of hard parameters makes the correctness a bit fuzzy. | V35: 3 | W35: It describes the expected behavior, but the parameters "barout", "baz", and "fooin" were omitted. | X35: https://github.com/isselab/2025-models-prompt-engineering-results/blob/main/experiment_samples/cycle_3/prompt_entry_380.txt | AA35: =ABS(F35-M35) -> 0 | AB35: =ABS(G35-N35) -> 1 | AC35: =ABS(H35-O35) -> 2 | AD35: =ABS(I35-P35) -> 0 | AE35: =ABS(J35-Q35) -> 1
A36: entry_552 | B36: https://github.com/isselab/2025-models-prompt-engineering-results/blob/main/experiment_samples/cycle_3/mrq_entry_552.txt | C36: 1 | D36: =AVERAGE(E36, L36) -> 3.2 | E36: =AVERAGE(F36, G36, H36, I36, J36) -> 3.4 | F36: 4 | G36: 3 | H36: 4 | I36: 2 | J36: 4 | K36: A few redundant phrases and expressions. Some expressions might not be interpreted precisely | L36: =AVERAGE(M36, N36, O36, P36, Q36) -> 3 | M36: 3 | N36: 3 | O36: 3 | P36: 2 | Q36: 4 | R36: Some requirements are hard to understand without context or more details. For instance, in R6, "mark them as unoccupied' is vague, and 'loci' seems like technical jargon. RQ6 (1-5) can be rearranged in terms of atomicity. | S36: =AVERAGE(T36, V36) -> 4 | T36: 4 | V36: 4 | X36: https://github.com/isselab/2025-models-prompt-engineering-results/blob/main/experiment_samples/cycle_3/prompt_entry_552.txt | AA36: =ABS(F36-M36) -> 1 | AB36: =ABS(G36-N36) -> 0 | AC36: =ABS(H36-O36) -> 1 | AD36: =ABS(I36-P36) -> 0 | AE36: =ABS(J36-Q36) -> 0
A37: Cycle 4
A38: entry_32 | B38: https://github.com/isselab/2025-models-prompt-engineering-results/blob/main/experiment_samples/cycle_4/mrq_entry_32.txt | C38: 4 | D38: =AVERAGE(E38, L38) -> 3.4 | E38: =AVERAGE(F38, G38, H38, I38, J38) -> 3.4 | F38: 3 | G38: 3 | H38: 4 | I38: 4 | J38: 3 | K38: Mission scope kept narrow and concise. Slight tradeoff of atomicity for fluency. More noticable fluency. "before proceeding" could me misinterpreted to mean other actions exist, slighly contadicting the last statement. | L38: =AVERAGE(M38, N38, O38, P38, Q38) -> 3.4 | M38: 4 | N38: 3 | O38: 4 | P38: 3 | Q38: 3 | R38: In the third sentence, "...wait for it to finish before proceeding." contradicts "a single-step mission". There is no other step. | S38: =AVERAGE(T38, V38) -> 4 | T38: 4 | V38: 4 | X38: https://github.com/isselab/2025-models-prompt-engineering-results/blob/main/experiment_samples/cycle_4/prompt_entry_32.txt | AA38: =ABS(F38-M38) -> 1 | AB38: =ABS(G38-N38) -> 0 | AC38: =ABS(H38-O38) -> 0 | AD38: =ABS(I38-P38) -> 1 | AE38: =ABS(J38-Q38) -> 0
A39: entry_41 | B39: https://github.com/isselab/2025-models-prompt-engineering-results/blob/main/experiment_samples/cycle_4/mrq_entry_41.txt | C39: 2 | D39: =AVERAGE(E39, L39) -> 3.5 | E39: =AVERAGE(F39, G39, H39, I39, J39) -> 3.6 | F39: 3 | G39: 4 | H39: 3 | I39: 4 | J39: 4 | K39: Slight tradeoff of atomicity for fluency. Succinctness in understadability make minor aspects of completeness more implicit(i.e failure of sequence actions) | L39: =AVERAGE(M39, N39, O39, P39, Q39) -> 3.4 | M39: 3 | N39: 3 | O39: 4 | P39: 3 | Q39: 4 | R39: The second sentence is a bit ambiguous: "...stop the sequence if any action fails or is still running.". Maybe: "will wait if an action is still running". I suggest splitting it for better clarity. | S39: =AVERAGE(T39, V39) -> 4 | T39: 4 | V39: 4 | X39: https://github.com/isselab/2025-models-prompt-engineering-results/blob/main/experiment_samples/cycle_4/prompt_entry_41.txt | AA39: =ABS(F39-M39) -> 0 | AB39: =ABS(G39-N39) -> 1 | AC39: =ABS(H39-O39) -> 1 | AD39: =ABS(I39-P39) -> 1 | AE39: =ABS(J39-Q39) -> 0
A40: entry_194 | B40: https://github.com/isselab/2025-models-prompt-engineering-results/blob/main/experiment_samples/cycle_4/mrq_entry_194.txt | C40: 2 | D40: =AVERAGE(E40, L40) -> 4 | E40: =AVERAGE(F40, G40, H40, I40, J40) -> 4 | F40: 4 | G40: 4 | H40: 4 | I40: 4 | J40: 4 | L40: =AVERAGE(M40, N40, O40, P40, Q40) -> 4 | M40: 4 | N40: 4 | O40: 4 | P40: 4 | Q40: 4 | S40: =AVERAGE(T40, V40) -> 4 | T40: 4 | V40: 4 | X40: https://github.com/isselab/2025-models-prompt-engineering-results/blob/main/experiment_samples/cycle_4/prompt_entry_194.txt | AA40: =ABS(F40-M40) -> 0 | AB40: =ABS(G40-N40) -> 0 | AC40: =ABS(H40-O40) -> 0 | AD40: =ABS(I40-P40) -> 0 | AE40: =ABS(J40-Q40) -> 0
...

Sheet KappaCalc
A1: Cycle 1 | I1: Cycle 1 | Q1: Cycle 1 | Y1: Cycle 1 | AG1: Cycle 1
D2: Atomicity | L2: Ambiguity | T2: Completeness | AB2: Usability | AJ2: Consistency
A3: Observed Freq. | D3: Evaluator | I3: Observed Freq. | L3: Evaluator | Q3: Observed Freq. | T3: Evaluator | Y3: Observed Freq. | AB3: Evaluator | AG3: Observed Freq. | AJ3: Evaluator
C4: 1 | D4: 2 | E4: 3 | F4: 4 | G4: Total | K4: 1 | L4: 2 | M4: 3 | N4: 4 | O4: Total | S4: 1 | T4: 2 | U4: 3 | V4: 4 | W4: Total | AA4: 1 | AB4: 2 | AC4: 3 | AD4: 4 | AE4: Total | AI4: 1 | AJ4: 2 | AK4: 3 | AL4: 4 | AM4: Total
B5: 1 | C5: =COUNTIFS(Datasheet!F5:F14,1, Datasheet!M5:M14,1) -> 0 | D5: =COUNTIFS(Datasheet!F5:F14,1, Datasheet!M5:M14,2) -> 4 | E5: =COUNTIFS(Datasheet!F5:F14,1, Datasheet!M5:M14,3) -> 0 | F5: =COUNTIFS(Datasheet!F5:F14,1, Datasheet!M5:M14,4) -> 1 | G5: =SUM(C5, D5, E5, F5)/10 -> 0.5 | J5: 1 | K5: =COUNTIFS(Datasheet!G5:G14,1, Datasheet!N5:N14,1) -> 0 | L5: =COUNTIFS(Datasheet!G5:G14,1, Datasheet!N5:N14,2) -> 0 | M5: =COUNTIFS(Datasheet!G5:G14,1, Datasheet!N5:N14,3) -> 0 | N5: =COUNTIFS(Datasheet!G5:G14,1, Datasheet!N5:N14,4) -> 0 | O5: =SUM(K5, L5, M5, N5)/10 -> 0 | R5: 1 | S5: =COUNTIFS(Datasheet!H5:H14,1, Datasheet!O5:O14,1) -> 0 | T5: =COUNTIFS(Datasheet!H5:H14,1, Datasheet!O5:O14,2) -> 0 | U5: =COUNTIFS(Datasheet!H5:H14,1, Datasheet!O5:O14,3) -> 0 | V5: =COUNTIFS(Datasheet!H5:H14,1, Datasheet!O5:O14,4) -> 1 | W5: =SUM(S5, T5, U5, V5)/10 -> 0.1 | Z5: 1 | AA5: =COUNTIFS(Datasheet!I5:I14,1, Datasheet!P5:P14,1) -> 10 | AB5: =COUNTIFS(Datasheet!I5:I14,1, Datasheet!P5:P14,2) -> 0 | AC5: =COUNTIFS(Datasheet!I5:I14,1, Datasheet!P5:P14,3) -> 0 | AD5: =COUNTIFS(Datasheet!I5:I14,1, Datasheet!P5:P14,4) -> 0 | AE5: =SUM(AA5, AB5, AC5, AD5)/10 -> 1 | AH5: 1 | AI5: =COUNTIFS(Datasheet!J5:J14,1, Datasheet!Q5:Q14,1) -> 0 | AJ5: =COUNTIFS(Datasheet!J5:J14,1, Datasheet!Q5:Q14,2) -> 0 | AK5: =COUNTIFS(Datasheet!J5:J14,1, Datasheet!Q5:Q14,3) -> 0 | AL5: =COUNTIFS(Datasheet!J5:J14,1, Datasheet!Q5:Q14,4) -> 0 | AM5: =SUM(AI5, AJ5, AK5, AL5)/10 -> 0
A6: Prompt Engineer | B6: 2 | C6: =COUNTIFS(Datasheet!F5:F14,2, Datasheet!M5:M14,1) -> 0 | D6: =COUNTIFS(Datasheet!F5:F14,2, Datasheet!M5:M14,2) -> 1 | E6: =COUNTIFS(Datasheet!F5:F14,2, Datasheet!M5:M14,3) -> 1 | F6: =COUNTIFS(Datasheet!F5:F14,2, Datasheet!M5:M14,4) -> 0 | G6: =SUM(C6, D6, E6, F6)/10 -> 0.2 | I6: Prompt Engineer | J6: 2 | K6: =COUNTIFS(Datasheet!G5:G14,2, Datasheet!N5:N14,1) -> 0 | L6: =COUNTIFS(Datasheet!G5:G14,2, Datasheet!N5:N14,2) -> 1 | M6: =COUNTIFS(Datasheet!G5:G14,2, Datasheet!N5:N14,3) -> 2 | N6: =COUNTIFS(Datasheet!G5:G14,2, Datasheet!N5:N14,4) -> 0 | O6: =SUM(K6, L6, M6, N6)/10 -> 0.3 | Q6: Prompt Engineer | R6: 2 | S6: =COUNTIFS(Datasheet!H5:H14,2, Datasheet!O5:O14,1) -> 0 | T6: =COUNTIFS(Datasheet!H5:H14,2, Datasheet!O5:O14,2) -> 0 | U6: =COUNTIFS(Datasheet!H5:H14,2, Datasheet!O5:O14,3) -> 0 | V6: =COUNTIFS(Datasheet!H5:H14,2, Datasheet!O5:O14,4) -> 1 | W6: =SUM(S6, T6, U6, V6)/10 -> 0.1 | Y6: Prompt Engineer | Z6: 2 | AA6: =COUNTIFS(Datasheet!I5:I14,2, Datasheet!P5:P14,1) -> 0 | AB6: =COUNTIFS(Datasheet!I5:I14,2, Datasheet!P5:P14,2) -> 0 | AC6: =COUNTIFS(Datasheet!I5:I14,2, Datasheet!P5:P14,3) -> 0 | AD6: =COUNTIFS(Datasheet!I5:I14,2, Datasheet!P5:P14,4) -> 0 | AE6: =SUM(AA6, AB6, AC6, AD6)/10 -> 0 | AG6: Prompt Engineer | AH6: 2 | AI6: =COUNTIFS(Datasheet!J5:J14,2, Datasheet!Q5:Q14,1) -> 0 | AJ6: =COUNTIFS(Datasheet!J5:J14,2, Datasheet!Q5:Q14,2) -> 0 | AK6: =COUNTIFS(Datasheet!J5:J14,2, Datasheet!Q5:Q14,3) -> 0 | AL6: =COUNTIFS(Datasheet!J5:J14,2, Datasheet!Q5:Q14,4) -> 0 | AM6: =SUM(AI6, AJ6, AK6, AL6)/10 -> 0
B7: 3 | C7: =COUNTIFS(Datasheet!F5:F14,3, Datasheet!M5:M14,1) -> 0 | D7: =COUNTIFS(Datasheet!F5:F14,3, Datasheet!M5:M14,2) -> 0 | E7: =COUNTIFS(Datasheet!F5:F14,3, Datasheet!M5:M14,3) -> 1 | F7: =COUNTIFS(Datasheet!F5:F14,3, Datasheet!M5:M14,4) -> 2 | G7: =SUM(C7, D7, E7, F7)/10 -> 0.3 | J7: 3 | K7: =COUNTIFS(Datasheet!G5:G14,3, Datasheet!N5:N14,1) -> 0 | L7: =COUNTIFS(Datasheet!G5:G14,3, Datasheet!N5:N14,2) -> 2 | M7: =COUNTIFS(Datasheet!G5:G14,3, Datasheet!N5:N14,3) -> 1 | N7: =COUNTIFS(Datasheet!G5:G14,3, Datasheet!N5:N14,4) -> 0 | O7: =SUM(K7, L7, M7, N7)/10 -> 0.3 | R7: 3 | S7: =COUNTIFS(Datasheet!H5:H14,3, Datasheet!O5:O14,1) -> 0 | T7: =COUNTIFS(Datasheet!H5:H14,3, Datasheet!O5:O14,2) -> 0 | U7: =COUNTIFS(Datasheet!H5:H14,3, Datasheet!O5:O14,3) -> 1 | V7: =COUNTIFS(Datasheet!H5:H14,3, Datasheet!O5:O14,4) -> 4 | W7: =SUM(S7, T7, U7, V7)/10 -> 0.5 | Z7: 3 | AA7: =COUNTIFS(Datasheet!I5:I14,3, Datasheet!P5:P14,1) -> 0 | AB7: =COUNTIFS(Datasheet!I5:I14,3, Datasheet!P5:P14,2) -> 0 | AC7: =COUNTIFS(Datasheet!I5:I14,3, Datasheet!P5:P14,3) -> 0 | AD7: =COUNTIFS(Datasheet!I5:I14,3, Datasheet!P5:P14,4) -> 0 | AE7: =SUM(AA7, AB7, AC7, AD7)/10 -> 0 | AH7: 3 | AI7: =COUNTIFS(Datasheet!J5:J14,3, Datasheet!Q5:Q14,1) -> 0 | AJ7: =COUNTIFS(Datasheet!J5:J14,3, Datasheet!Q5:Q14,2) -> 1 | AK7: =COUNTIFS(Datasheet!J5:J14,3, Datasheet!Q5:Q14,3) -> 2 | AL7: =COUNTIFS(Datasheet!J5:J14,3, Datasheet!Q5:Q14,4) -> 2 | AM7: =SUM(AI7, AJ7, AK7, AL7)/10 -> 0.5
B8: 4 | C8: =COUNTIFS(Datasheet!F5:F14,4, Datasheet!M5:M14,1) -> 0 | D8: =COUNTIFS(Datasheet!F5:F14,4, Datasheet!M5:M14,2) -> 0 | E8: =COUNTIFS(Datasheet!F5:F14,4, Datasheet!M5:M14,3) -> 0 | F8: =COUNTIFS(Datasheet!F5:F14,4, Datasheet!M5:M14,4) -> 0 | G8: =SUM(C8, D8, E8, F8)/10 -> 0 | J8: 4 | K8: =COUNTIFS(Datasheet!G5:G14,4, Datasheet!N5:N14,1) -> 0 | L8: =COUNTIFS(Datasheet!G5:G14,4, Datasheet!N5:N14,2) -> 4 | M8: =COUNTIFS(Datasheet!G5:G14,4, Datasheet!N5:N14,3) -> 0 | N8: =COUNTIFS(Datasheet!G5:G14,4, Datasheet!N5:N14,4) -> 0 | O8: =SUM(K8, L8, M8, N8)/10 -> 0.4 | R8: 4 | S8: =COUNTIFS(Datasheet!H5:H14,4, Datasheet!O5:O14,1) -> 0 | T8: =COUNTIFS(Datasheet!H5:H14,4, Datasheet!O5:O14,2) -> 1 | U8: =COUNTIFS(Datasheet!H5:H14,4, Datasheet!O5:O14,3) -> 1 | V8: =COUNTIFS(Datasheet!H5:H14,4, Datasheet!O5:O14,4) -> 1 | W8: =SUM(S8, T8, U8, V8)/10 -> 0.3 | Z8: 4 | AA8: =COUNTIFS(Datasheet!I5:I14,4, Datasheet!P5:P14,1) -> 0 | AB8: =COUNTIFS(Datasheet!I5:I14,4, Datasheet!P5:P14,2) -> 0 | AC8: =COUNTIFS(Datasheet!I5:I14,4, Datasheet!P5:P14,3) -> 0 | AD8: =COUNTIFS(Datasheet!I5:I14,4, Datasheet!P5:P14,4) -> 0 | AE8: =SUM(AA8, AB8, AC8, AD8)/10 -> 0 | AH8: 4 | AI8: =COUNTIFS(Datasheet!J5:J14,4, Datasheet!Q5:Q14,1) -> 0 | AJ8: =COUNTIFS(Datasheet!J5:J14,4, Datasheet!Q5:Q14,2) -> 0 | AK8: =COUNTIFS(Datasheet!J5:J14,4, Datasheet!Q5:Q14,3) -> 3 | AL8: =COUNTIFS(Datasheet!J5:J14,4, Datasheet!Q5:Q14,4) -> 2 | AM8: =SUM(AI8, AJ8, AK8, AL8)/10 -> 0.5
B9: Total | C9: =SUM(C5:C8)/10 -> 0 | D9: =SUM(D5:D8)/10 -> 0.5 | E9: =SUM(E5:E8)/10 -> 0.2 | F9: =SUM(F5:F8)/10 -> 0.3 | G9: =SUM(G5:G8) -> 1 | J9: Total | K9: =SUM(K5:K8)/10 -> 0 | L9: =SUM(L5:L8)/10 -> 0.7 | M9: =SUM(M5:M8)/10 -> 0.3 | N9: =SUM(N5:N8)/10 -> 0 | O9: =SUM(O5:O8) -> 1 | R9: Total | S9: =SUM(S5:S8)/10 -> 0 | T9: =SUM(T5:T8)/10 -> 0.1 | U9: =SUM(U5:U8)/10 -> 0.2 | V9: =SUM(V5:V8)/10 -> 0.7 | W9: =SUM(W5:W8) -> 1 | Z9: Total | AA9: =SUM(AA5:AA8)/10 -> 1 | AB9: =SUM(AB5:AB8)/10 -> 0 | AC9: =SUM(AC5:AC8)/10 -> 0 | AD9: =SUM(AD5:AD8)/10 -> 0 | AE9: =SUM(AE5:AE8) -> 1 | AH9: Total | AI9: =SUM(AI5:AI8)/10 -> 0 | AJ9: =SUM(AJ5:AJ8)/10 -> 0.1 | AK9: =SUM(AK5:AK8)/10 -> 0.5 | AL9: =SUM(AL5:AL8)/10 -> 0.4 | AM9: =SUM(AM5:AM8) -> 1
A11: Expected Freq | C11: =(G5*C9)*10 -> 0 | D11: =(G5*D9)*10 -> 2.5 | E11: =(G5*E9)*10 -> 1 | F11: =(G5*F9)*10 -> 1.5 | I11: Expected Freq | K11: =(O5*K9)*10 -> 0 | L11: =(O5*L9)*10 -> 0 | M11: =(O5*M9)*10 -> 0 | N11: =(O5*N9)*10 -> 0 | Q11: Expected Freq | S11: =(W5*S9)*10 -> 0 | T11: =(W5*T9)*10 -> 0.1 | U11: =(W5*U9)*10 -> 0.2 | V11: =(W5*V9)*10 -> 0.7 | Y11: Expected Freq | AA11: =(AE5*AA9)*10 -> 10 | AB11: =(AE5*AB9)*10 -> 0 | AC11: =(AE5*AC9)*10 -> 0 | AD11: =(AE5*AD9)*10 -> 0 | AG11: Expected Freq | AI11: =(AM5*AI9)*10 -> 0 | AJ11: =(AM5*AJ9)*10 -> 0 | AK11: =(AM5*AK9)*10 -> 0 | AL11: =(AM5*AL9)*10 -> 0
C12: =(G6*C9)*10 -> 0 | D12: =(G6*D9)*10 -> 1 | E12: =(G6*E9)*10 -> 0.4 | F12: =(G6*F9)*10 -> 0.6 | K12: =(O6*K9)*10 -> 0 | L12: =(O6*L9)*10 -> 2.1 | M12: =(O6*M9)*10 -> 0.9 | N12: =(O6*N9)*10 -> 0 | S12: =(W6*S9)*10 -> 0 | T12: =(W6*T9)*10 -> 0.1 | U12: =(W6*U9)*10 -> 0.2 | V12: =(W6*V9)*10 -> 0.7 | AA12: =(AE6*AA9)*10 -> 0 | AB12: =(AE6*AB9)*10 -> 0 | AC12: =(AE6*AC9)*10 -> 0 | AD12: =(AE6*AD9)*10 -> 0 | AI12: =(AM6*AI9)*10 -> 0 | AJ12: =(AM6*AJ9)*10 -> 0 | AK12: =(AM6*AK9)*10 -> 0 | AL12: =(AM6*AL9)*10 -> 0
C13: =(G7*C9)*10 -> 0 | D13: =(G7*D9)*10 -> 1.5 | E13: =(G7*E9)*10 -> 0.6 | F13: =(G7*F9)*10 -> 0.9 | K13: =(O7*K9)*10 -> 0 | L13: =(O7*L9)*10 -> 2.1 | M13: =(O7*M9)*10 -> 0.9 | N13: =(O7*N9)*10 -> 0 | S13: =(W7*S9)*10 -> 0 | T13: =(W7*T9)*10 -> 0.5 | U13: =(W7*U9)*10 -> 1 | V13: =(W7*V9)*10 -> 3.5 | AA13: =(AE7*AA9)*10 -> 0 | AB13: =(AE7*AB9)*10 -> 0 | AC13: =(AE7*AC9)*10 -> 0 | AD13: =(AE7*AD9)*10 -> 0 | AI13: =(AM7*AI9)*10 -> 0 | AJ13: =(AM7*AJ9)*10 -> 0.5 | AK13: =(AM7*AK9)*10 -> 2.5 | AL13: =(AM7*AL9)*10 -> 2
C14: =(G8*C9)*10 -> 0 | D14: =(G8*D9)*10 -> 0 | E14: =(G8*E9)*10 -> 0 | F14: =(G8*F9)*10 -> 0 | K14: =(O8*K9)*10 -> 0 | L14: =(O8*L9)*10 -> 2.8 | M14: =(O8*M9)*10 -> 1.2 | N14: =(O8*N9)*10 -> 0 | S14: =(W8*S9)*10 -> 0 | T14: =(W8*T9)*10 -> 0.3 | U14: =(W8*U9)*10 -> 0.6 | V14: =(W8*V9)*10 -> 2.1 | AA14: =(AE8*AA9)*10 -> 0 | AB14: =(AE8*AB9)*10 -> 0 | AC14: =(AE8*AC9)*10 -> 0 | AD14: =(AE8*AD9)*10 -> 0 | AI14: =(AM8*AI9)*10 -> 0 | AJ14: =(AM8*AJ9)*10 -> 0.5 | AK14: =(AM8*AK9)*10 -> 2.5 | AL14: =(AM8*AL9)*10 -> 2
A16: Quad. Weighting | C16: =((B5-C4)^2)/((4-1)^2) -> 0 | D16: =((B5-D4)^2)/((4-1)^2) -> 0.11111111 | E16: =((B5-E4)^2)/((4-1)^2) -> 0.44444444 | F16: =((B5-F4)^2)/((4-1)^2) -> 1 | I16: Quad. Weighting | K16: =((J5-K4)^2)/((4-1)^2) -> 0 | L16: =((J5-L4)^2)/((4-1)^2) -> 0.11111111 | M16: =((J5-M4)^2)/((4-1)^2) -> 0.44444444 | N16: =((J5-N4)^2)/((4-1)^2) -> 1 | Q16: Quad. Weighting | S16: =((R5-S4)^2)/((4-1)^2) -> 0 | T16: =((R5-T4)^2)/((4-1)^2) -> 0.11111111 | U16: =((R5-U4)^2)/((4-1)^2) -> 0.44444444 | V16: =((R5-V4)^2)/((4-1)^2) -> 1 | Y16: Quad. Weighting | AA16: =((Z5-AA4)^2)/((4-1)^2) -> 0 | AB16: =((Z5-AB4)^2)/((4-1)^2) -> 0.11111111 | AC16: =((Z5-AC4)^2)/((4-1)^2) -> 0.44444444 | AD16: =((Z5-AD4)^2)/((4-1)^2) -> 1 | AG16: Quad. Weighting | AI16: =((AH5-AI4)^2)/((4-1)^2) -> 0 | AJ16: =((AH5-AJ4)^2)/((4-1)^2) -> 0.11111111 | AK16: =((AH5-AK4)^2)/((4-1)^2) -> 0.44444444 | AL16: =((AH5-AL4)^2)/((4-1)^2) -> 1
C17: =((B6-C4)^2)/((4-1)^2) -> 0.11111111 | D17: =((B6-D4)^2)/((4-1)^2) -> 0 | E17: =((B6-E4)^2)/((4-1)^2) -> 0.11111111 | F17: =((B6-F4)^2)/((4-1)^2) -> 0.44444444 | K17: =((J6-K4)^2)/((4-1)^2) -> 0.11111111 | L17: =((J6-L4)^2)/((4-1)^2) -> 0 | M17: =((J6-M4)^2)/((4-1)^2) -> 0.11111111 | N17: =((J6-N4)^2)/((4-1)^2) -> 0.44444444 | S17: =((R6-S4)^2)/((4-1)^2) -> 0.11111111 | T17: =((R6-T4)^2)/((4-1)^2) -> 0 | U17: =((R6-U4)^2)/((4-1)^2) -> 0.11111111 | V17: =((R6-V4)^2)/((4-1)^2) -> 0.44444444 | AA17: =((Z6-AA4)^2)/((4-1)^2) -> 0.11111111 | AB17: =((Z6-AB4)^2)/((4-1)^2) -> 0 | AC17: =((Z6-AC4)^2)/((4-1)^2) -> 0.11111111 | AD17: =((Z6-AD4)^2)/((4-1)^2) -> 0.44444444 | AI17: =((AH6-AI4)^2)/((4-1)^2) -> 0.11111111 | AJ17: =((AH6-AJ4)^2)/((4-1)^2) -> 0 | AK17: =((AH6-AK4)^2)/((4-1)^2) -> 0.11111111 | AL17: =((AH6-AL4)^2)/((4-1)^2) -> 0.44444444
C18: =((B7-C4)^2)/((4-1)^2) -> 0.44444444 | D18: =((B7-D4)^2)/((4-1)^2) -> 0.11111111 | E18: =((B7-E4)^2)/((4-1)^2) -> 0 | F18: =((B7-F4)^2)/((4-1)^2) -> 0.11111111 | K18: =((J7-K4)^2)/((4-1)^2) -> 0.44444444 | L18: =((J7-L4)^2)/((4-1)^2) -> 0.11111111 | M18: =((J7-M4)^2)/((4-1)^2) -> 0 | N18: =((J7-N4)^2)/((4-1)^2) -> 0.11111111 | S18: =((R7-S4)^2)/((4-1)^2) -> 0.44444444 | T18: =((R7-T4)^2)/((4-1)^2) -> 0.11111111 | U18: =((R7-U4)^2)/((4-1)^2) -> 0 | V18: =((R7-V4)^2)/((4-1)^2) -> 0.11111111 | AA18: =((Z7-AA4)^2)/((4-1)^2) -> 0.44444444 | AB18: =((Z7-AB4)^2)/((4-1)^2) -> 0.11111111 | AC18: =((Z7-AC4)^2)/((4-1)^2) -> 0 | AD18: =((Z7-AD4)^2)/((4-1)^2) -> 0.11111111 | AI18: =((AH7-AI4)^2)/((4-1)^2) -> 0.44444444 | AJ18: =((AH7-AJ4)^2)/((4-1)^2) -> 0.11111111 | AK18: =((AH7-AK4)^2)/((4-1)^2) -> 0 | AL18: =((AH7-AL4)^2)/((4-1)^2) -> 0.11111111
C19: =((B8-C4)^2)/((4-1)^2) -> 1 | D19: =((B8-D4)^2)/((4-1)^2) -> 0.44444444 | E19: =((B8-E4)^2)/((4-1)^2) -> 0.11111111 | F19: =((B8-F4)^2)/((4-1)^2) -> 0 | K19: =((J8-K4)^2)/((4-1)^2) -> 1 | L19: =((J8-L4)^2)/((4-1)^2) -> 0.44444444 | M19: =((J8-M4)^2)/((4-1)^2) -> 0.11111111 | N19: =((J8-N4)^2)/((4-1)^2) -> 0 | S19: =((R8-S4)^2)/((4-1)^2) -> 1 | T19: =((R8-T4)^2)/((4-1)^2) -> 0.44444444 | U19: =((R8-U4)^2)/((4-1)^2) -> 0.11111111 | V19: =((R8-V4)^2)/((4-1)^2) -> 0 | AA19: =((Z8-AA4)^2)/((4-1)^2) -> 1 | AB19: =((Z8-AB4)^2)/((4-1)^2) -> 0.44444444 | AC19: =((Z8-AC4)^2)/((4-1)^2) -> 0.11111111 | AD19: =((Z8-AD4)^2)/((4-1)^2) -> 0 | AI19: =((AH8-AI4)^2)/((4-1)^2) -> 1 | AJ19: =((AH8-AJ4)^2)/((4-1)^2) -> 0.44444444 | AK19: =((AH8-AK4)^2)/((4-1)^2) -> 0.11111111 | AL19: =((AH8-AL4)^2)/((4-1)^2) -> 0
A21: W. Kappa | B21: =1-(SUMPRODUCT(C5:F8,C16:F19)/SUMPRODUCT(C11:F14,C16:F19)) -> 0.36507937 | I21: W. Kappa | J21: =1-SUMPRODUCT(K5:N8,K16:N19)/SUMPRODUCT(K11:N14,K16:N19) -> -0.2987013 | Q21: W. Kappa | R21: =1-SUMPRODUCT(S5:V8,S16:V19)/SUMPRODUCT(S11:V14,S16:V19) -> -0.375 | Y21: W. Kappa | Z21: =1-IFERROR(SUMPRODUCT(AA5:AD8,AA16:AD19)/SUMPRODUCT(AA11:AD14,AA16:AD19),0) -> 1 | AG21: W. Kappa | AH21: =1-SUMPRODUCT(AI5:AL8,AI16:AL19)/SUMPRODUCT(AI11:AL14,AI16:AL19) -> 0.14285714
A23: Cycle 2 | I23: Cycle 2 | Q23: Cycle 2 | Y23: Cycle 2 | AG23: Cycle 2
D24: Atomicity | L24: Ambiguity | T24: Completeness | AB24: Usability | AJ24: Consistency
A25: Observed Freq. | D25: Evaluator | I25: Observed Freq. | L25: Evaluator | Q25: Observed Freq. | T25: Evaluator | Y25: Observed Freq. | AB25: Evaluator | AG25: Observed Freq. | AJ25: Evaluator
C26: 1 | D26: 2 | E26: 3 | F26: 4 | G26: Total | K26: 1 | L26: 2 | M26: 3 | N26: 4 | O26: Total | S26: 1 | T26: 2 | U26: 3 | V26: 4 | W26: Total | AA26: 1 | AB26: 2 | AC26: 3 | AD26: 4 | AE26: Total | AI26: 1 | AJ26: 2 | AK26: 3 | AL26: 4 | AM26: Total
B27: 1 | C27: =COUNTIFS(Datasheet!F16:F25,1, Datasheet!M16:M25,1) -> 0 | D27: =COUNTIFS(Datasheet!F16:F25,1, Datasheet!M16:M25,2) -> 0 | E27: =COUNTIFS(Datasheet!F16:F25,1, Datasheet!M16:M25,3) -> 0 | F27: =COUNTIFS(Datasheet!F16:F25,1, Datasheet!M16:M25,4) -> 0 | G27: =SUM(C27, D27, E27, F27)/10 -> 0 | J27: 1 | K27: =COUNTIFS(Datasheet!G16:G25,1, Datasheet!N16:N25,1) -> 0 | L27: =COUNTIFS(Datasheet!G16:G25,1, Datasheet!N16:N25,2) -> 0 | M27: =COUNTIFS(Datasheet!G16:G25,1, Datasheet!N16:N25,3) -> 0 | N27: =COUNTIFS(Datasheet!G16:G25,1, Datasheet!N16:N25,4) -> 0 | O27: =SUM(K27, L27, M27, N27)/10 -> 0 | R27: 1 | S27: =COUNTIFS(Datasheet!H16:H25,1, Datasheet!O16:O25,1) -> 0 | T27: =COUNTIFS(Datasheet!H16:H25,1, Datasheet!O16:O25,2) -> 0 | U27: =COUNTIFS(Datasheet!H16:H25,1, Datasheet!O16:O25,3) -> 0 | V27: =COUNTIFS(Datasheet!H16:H25,1, Datasheet!O16:O25,4) -> 0 | W27: =SUM(S27, T27, U27, V27)/10 -> 0 | Z27: 1 | AA27: =COUNTIFS(Datasheet!I16:I25,1, Datasheet!P16:P25,1) -> 6 | AB27: =COUNTIFS(Datasheet!I16:I25,1, Datasheet!P16:P25,2) -> 0 | AC27: =COUNTIFS(Datasheet!I16:I25,1, Datasheet!P16:P25,3) -> 0 | AD27: =COUNTIFS(Datasheet!I16:I25,1, Datasheet!P16:P25,4) -> 0 | AE27: =SUM(AA27, AB27, AC27, AD27)/10 -> 0.6 | AH27: 1 | AI27: =COUNTIFS(Datasheet!J16:J25,1, Datasheet!Q16:Q25,1) -> 0 | AJ27: =COUNTIFS(Datasheet!J16:J25,1, Datasheet!Q16:Q25,2) -> 0 | AK27: =COUNTIFS(Datasheet!J16:J25,1, Datasheet!Q16:Q25,3) -> 0 | AL27: =COUNTIFS(Datasheet!J16:J25,1, Datasheet!Q16:Q25,4) -> 0 | AM27: =SUM(AI27, AJ27, AK27, AL27)/10 -> 0
A28: Prompt Engineer | B28: 2 | C28: =COUNTIFS(Datasheet!F16:F25,2, Datasheet!M16:M25,1) -> 0 | D28: =COUNTIFS(Datasheet!F16:F25,2, Datasheet!M16:M25,2) -> 0 | E28: =COUNTIFS(Datasheet!F16:F25,2, Datasheet!M16:M25,3) -> 0 | F28: =COUNTIFS(Datasheet!F16:F25,2, Datasheet!M16:M25,4) -> 1 | G28: =SUM(C28, D28, E28, F28)/10 -> 0.1 | I28: Prompt Engineer | J28: 2 | K28: =COUNTIFS(Datasheet!G16:G25,2, Datasheet!N16:N25,1) -> 0 | L28: =COUNTIFS(Datasheet!N16:N25,2, Datasheet!U16:U25,2) -> 0 | M28: =COUNTIFS(Datasheet!G16:G25,2, Datasheet!N16:N25,3) -> 1 | N28: =COUNTIFS(Datasheet!G16:G25,2, Datasheet!N16:N25,4) -> 0 | O28: =SUM(K28, L28, M28, N28)/10 -> 0.1 | Q28: Prompt Engineer | R28: 2 | S28: =COUNTIFS(Datasheet!H16:H25,2, Datasheet!O16:O25,1) -> 0 | T28: =COUNTIFS(Datasheet!H16:H25,2, Datasheet!O16:O25,2) -> 0 | U28: =COUNTIFS(Datasheet!H16:H25,2, Datasheet!O16:O25,3) -> 0 | V28: =COUNTIFS(Datasheet!H16:H25,2, Datasheet!O16:O25,4) -> 1 | W28: =SUM(S28, T28, U28, V28)/10 -> 0.1 | Y28: Prompt Engineer | Z28: 2 | AA28: =COUNTIFS(Datasheet!I16:I25,2, Datasheet!P16:P25,1) -> 2 | AB28: =COUNTIFS(Datasheet!I16:I25,2, Datasheet!P16:P25,2) -> 2 | AC28: =COUNTIFS(Datasheet!I16:I25,2, Datasheet!P16:P25,3) -> 0 | AD28: =COUNTIFS(Datasheet!I16:I25,2, Datasheet!P16:P25,4) -> 0 | AE28: =SUM(AA28, AB28, AC28, AD28)/10 -> 0.4 | AG28: Prompt Engineer | AH28: 2 | AI28: =COUNTIFS(Datasheet!J16:J25,2, Datasheet!Q16:Q25,1) -> 0 | AJ28: =COUNTIFS(Datasheet!J16:J25,2, Datasheet!Q16:Q25,2) -> 0 | AK28: =COUNTIFS(Datasheet!J16:J25,2, Datasheet!Q16:Q25,3) -> 0 | AL28: =COUNTIFS(Datasheet!J16:J25,2, Datasheet!Q16:Q25,4) -> 0 | AM28: =SUM(AI28, AJ28, AK28, AL28)/10 -> 0
B29: 3 | C29: =COUNTIFS(Datasheet!F16:F25,3, Datasheet!M16:M25,1) -> 0 | D29: =COUNTIFS(Datasheet!F16:F25,3, Datasheet!M16:M25,2) -> 0 | E29: =COUNTIFS(Datasheet!F16:F25,3, Datasheet!M16:M25,3) -> 4 | F29: =COUNTIFS(Datasheet!F16:F25,3, Datasheet!M16:M25,4) -> 4 | G29: =SUM(C29, D29, E29, F29)/10 -> 0.8 | J29: 3 | K29: =COUNTIFS(Datasheet!G16:G25,3, Datasheet!N16:N25,1) -> 0 | L29: =COUNTIFS(Datasheet!N16:N25,3, Datasheet!U16:U25,2) -> 0 | M29: =COUNTIFS(Datasheet!G16:G25,3, Datasheet!N16:N25,3) -> 0 | N29: =COUNTIFS(Datasheet!G16:G25,3, Datasheet!N16:N25,4) -> 0 | O29: =SUM(K29, L29, M29, N29)/10 -> 0 | R29: 3 | S29: =COUNTIFS(Datasheet!H16:H25,3, Datasheet!O16:O25,1) -> 0 | T29: =COUNTIFS(Datasheet!H16:H25,3, Datasheet!O16:O25,2) -> 0 | U29: =COUNTIFS(Datasheet!H16:H25,3, Datasheet!O16:O25,3) -> 1 | V29: =COUNTIFS(Datasheet!H16:H25,3, Datasheet!O16:O25,4) -> 4 | W29: =SUM(S29, T29, U29, V29)/10 -> 0.5 | Z29: 3 | AA29: =COUNTIFS(Datasheet!I16:I25,3, Datasheet!P16:P25,1) -> 0 | AB29: =COUNTIFS(Datasheet!I16:I25,3, Datasheet!P16:P25,2) -> 0 | AC29: =COUNTIFS(Datasheet!I16:I25,3, Datasheet!P16:P25,3) -> 0 | AD29: =COUNTIFS(Datasheet!I16:I25,3, Datasheet!P16:P25,4) -> 0 | AE29: =SUM(AA29, AB29, AC29, AD29)/10 -> 0 | AH29: 3 | AI29: =COUNTIFS(Datasheet!J16:J25,3, Datasheet!Q16:Q25,1) -> 0 | AJ29: =COUNTIFS(Datasheet!J16:J25,3, Datasheet!Q16:Q25,2) -> 0 | AK29: =COUNTIFS(Datasheet!J16:J25,3, Datasheet!Q16:Q25,3) -> 0 | AL29: =COUNTIFS(Datasheet!J16:J25,3, Datasheet!Q16:Q25,4) -> 5 | AM29: =SUM(AI29, AJ29, AK29, AL29)/10 -> 0.5
B30: 4 | C30: =COUNTIFS(Datasheet!F16:F25,4, Datasheet!M16:M25,1) -> 0 | D30: =COUNTIFS(Datasheet!F16:F25,4, Datasheet!M16:M25,2) -> 0 | E30: =COUNTIFS(Datasheet!F16:F25,4, Datasheet!M16:M25,3) -> 0 | F30: =COUNTIFS(Datasheet!F16:F25,4, Datasheet!M16:M25,4) -> 1 | G30: =SUM(C30, D30, E30, F30)/10 -> 0.1 | J30: 4 | K30: =COUNTIFS(Datasheet!G16:G25,4, Datasheet!N16:N25,1) -> 0 | L30: =COUNTIFS(Datasheet!N16:N25,4, Datasheet!U16:U25,2) -> 0 | M30: =COUNTIFS(Datasheet!G16:G25,4, Datasheet!N16:N25,3) -> 3 | N30: =COUNTIFS(Datasheet!G16:G25,4, Datasheet!N16:N25,4) -> 0 | O30: =SUM(K30, L30, M30, N30)/10 -> 0.3 | R30: 4 | S30: =COUNTIFS(Datasheet!H16:H25,4, Datasheet!O16:O25,1) -> 0 | T30: =COUNTIFS(Datasheet!H16:H25,4, Datasheet!O16:O25,2) -> 0 | U30: =COUNTIFS(Datasheet!H16:H25,4, Datasheet!O16:O25,3) -> 0 | V30: =COUNTIFS(Datasheet!H16:H25,4, Datasheet!O16:O25,4) -> 4 | W30: =SUM(S30, T30, U30, V30)/10 -> 0.4 | Z30: 4 | AA30: =COUNTIFS(Datasheet!I16:I25,4, Datasheet!P16:P25,1) -> 0 | AB30: =COUNTIFS(Datasheet!I16:I25,4, Datasheet!P16:P25,2) -> 0 | AC30: =COUNTIFS(Datasheet!I16:I25,4, Datasheet!P16:P25,3) -> 0 | AD30: =COUNTIFS(Datasheet!I16:I25,4, Datasheet!P16:P25,4) -> 0 | AE30: =SUM(AA30, AB30, AC30, AD30)/10 -> 0 | AH30: 4 | AI30: =COUNTIFS(Datasheet!J16:J25,4, Datasheet!Q16:Q25,1) -> 0 | AJ30: =COUNTIFS(Datasheet!J16:J25,4, Datasheet!Q16:Q25,2) -> 0 | AK30: =COUNTIFS(Datasheet!J16:J25,4, Datasheet!Q16:Q25,3) -> 0 | AL30: =COUNTIFS(Datasheet!J16:J25,4, Datasheet!Q16:Q25,4) -> 5 | AM30: =SUM(AI30, AJ30, AK30, AL30)/10 -> 0.5
B31: Total | C31: =SUM(C27:C30)/10 -> 0 | D31: =SUM(D27:D30)/10 -> 0 | E31: =SUM(E27:E30)/10 -> 0.4 | F31: =SUM(F27:F30)/10 -> 0.6 | G31: =SUM(G27:G30) -> 1 | J31: Total | K31: =SUM(K27:K30)/10 -> 0 | L31: =SUM(L27:L30)/10 -> 0 | M31: =SUM(M27:M30)/10 -> 0.4 | N31: =SUM(N27:N30)/10 -> 0 | O31: =SUM(O27:O30) -> 0.4 | R31: Total | S31: =SUM(S27:S30)/10 -> 0 | T31: =SUM(T27:T30)/10 -> 0 | U31: =SUM(U27:U30)/10 -> 0.1 | V31: =SUM(V27:V30)/10 -> 0.9 | W31: =SUM(W27:W30) -> 1 | Z31: Total | AA31: =SUM(AA27:AA30)/10 -> 0.8 | AB31: =SUM(AB27:AB30)/10 -> 0.2 | AC31: =SUM(AC27:AC30)/10 -> 0 | AD31: =SUM(AD27:AD30)/10 -> 0 | AE31: =SUM(AE27:AE30) -> 1 | AH31: Total | AI31: =SUM(AI27:AI30)/10 -> 0 | AJ31: =SUM(AJ27:AJ30)/10 -> 0 | AK31: =SUM(AK27:AK30)/10 -> 0 | AL31: =SUM(AL27:AL30)/10 -> 1 | AM31: =SUM(AM27:AM30) -> 1
A33: Expected Freq | C33: =(G27*C31)*10 -> 0 | D33: =(G27*D31)*10 -> 0 | E33: =(G27*E31)*10 -> 0 | F33: =(G27*F31)*10 -> 0 | I33: Expected Freq | K33: =(O27*K31)*10 -> 0 | L33: =(O27*L31)*10 -> 0 | M33: =(O27*M31)*10 -> 0 | N33: =(O27*N31)*10 -> 0 | Q33: Expected Freq | S33: =(W27*S31)*10 -> 0 | T33: =(W27*T31)*10 -> 0 | U33: =(W27*U31)*10 -> 0 | V33: =(W27*V31)*10 -> 0 | Y33: Expected Freq | AA33: =(AE27*AA31)*10 -> 4.8 | AB33: =(AE27*AB31)*10 -> 1.2 | AC33: =(AE27*AC31)*10 -> 0 | AD33: =(AE27*AD31)*10 -> 0 | AG33: Expected Freq | AI33: =(AM27*AI31)*10 -> 0 | AJ33: =(AM27*AJ31)*10 -> 0 | AK33: =(AM27*AK31)*10 -> 0 | AL33: =(AM27*AL31)*10 -> 0
